#VRML_SIM R2020b utf8
# license: Apache License 2.0
# license url: http://www.apache.org/licenses/LICENSE-2.0
# This is a proto file for Webots for the ForkliftRobot
# Extracted from: urdf/forklift_robot.urdf

PROTO ForkliftRobot [
  field  SFVec3f     translation     0 0 0
  field  SFRotation  rotation        1 0 0 -1.5708
  field  SFString    name            "ForkliftRobot"  # Is `Robot.name`.
  field  SFString    controller      "void"           # Is `Robot.controller`.
  field  MFString    controllerArgs  []               # Is `Robot.controllerArgs`.
  field  SFString    customData      ""               # Is `Robot.customData`.
  field  SFBool      supervisor      FALSE            # Is `Robot.supervisor`.
  field  SFBool      synchronization TRUE             # Is `Robot.synchronization`.
  field  SFBool      selfCollision   FALSE            # Is `Robot.selfCollision`.
]
{
  Robot {
    translation IS translation
    rotation IS rotation
    controller IS controller
    controllerArgs IS controllerArgs
    customData IS customData
    supervisor IS supervisor
    synchronization IS synchronization
    selfCollision IS selfCollision
    children [
      Transform {
        translation -1.079500 -0.533400 0.000000
        rotation 0.000000 1.000000 0.000000 0.000000
        children [
          ForkliftRobot_base_link_0Mesh {
          }
        ]
      }
      SliderJoint {
        jointParameters JointParameters {
          axis 0.000000 0.000000 1.000000
          dampingConstant 0.0
          staticFriction 0.0
        }
        device [
          LinearMotor {
            name "base_to_fork"
            maxVelocity 0.1
            maxPosition 2.0
            maxForce 100.0
          }
          PositionSensor {
            name "base_to_fork_sensor"
          }
        ]
        endPoint Solid {
          translation 1.079500 -0.368600 0.000000
          rotation 1.000000 0.000000 0.000000 0.000000
          children [
            ForkliftRobot_fork_0Mesh {
            }
          ]
          name "fork"
          boundingObject IndexedFaceSet {
            coord Coordinate {
              point [
                0.012700 0.127000 0.430187, 0.000000 0.000000 0.430187, 0.000000 0.736600 0.430187, 0.012700 0.127000 0.609600, 0.012700 0.127000 0.125387, 0.012700 0.609600 0.125387, 0.012700 0.609600 0.049187, 0.000000 0.736600 0.125387, 0.000000 0.736600 0.049187, 0.012700 0.736600 0.609600, 1.384300 0.736600 0.006350, 1.384300 0.736600 0.000000, 1.384300 0.609600 0.006350, 0.063500 0.609600 0.609600, 0.012700 0.609600 0.609600, 0.012700 0.609600 0.506387, 0.012700 0.609600 0.430187, 0.063500 0.609600 0.050800, 0.012700 0.609600 0.000000, 1.384300 0.609600 0.000000, 0.063500 0.736600 0.609600, 0.012700 0.736600 0.430187, 0.012700 0.736600 0.125387, 0.063500 0.736600 0.050800, 0.012700 0.736600 0.000000, 0.012700 0.736600 0.049187, 0.000000 0.736600 0.506387, 0.012700 0.736600 0.506387, 0.012700 0.127000 0.049187, 0.012700 0.000000 0.609600, 0.012700 0.127000 0.000000, 1.384300 0.000000 0.000000, 1.384300 0.000000 0.006350, 0.063500 0.000000 0.609600, 0.012700 0.000000 0.506387, 0.063500 0.000000 0.050800, 0.000000 0.000000 0.049187, 0.012700 0.000000 0.125387, 0.000000 0.000000 0.125387, 0.000000 0.000000 0.506387, 0.012700 0.000000 0.430187, 0.012700 0.000000 0.049187, 0.012700 0.000000 0.000000, 0.063500 0.127000 0.609600, 0.012700 0.127000 0.506387, 0.063500 0.127000 0.050800, 1.384300 0.127000 0.000000, 1.384300 0.127000 0.006350, 
              ]
            }
            coordIndex [
              15 44 16 -1 16 44 0 -1 34 44 39 -1 39 44 15 -1 39 15 26 -1 26 15 27 -1 40 1 0 -1 0 1 2 -1 0 2 16 -1 16 2 21 -1 1 39 2 -1 2 39 26 -1 15 14 27 -1 27 14 9 -1 21 22 16 -1 16 22 5 -1 34 29 44 -1 44 29 3 -1 0 4 40 -1 40 4 37 -1 28 6 4 -1 4 6 5 -1 25 6 8 -1 8 6 28 -1 8 28 36 -1 36 28 41 -1 22 7 5 -1 5 7 38 -1 5 38 4 -1 4 38 37 -1 7 8 38 -1 38 8 36 -1 25 24 6 -1 6 24 18 -1 9 14 20 -1 20 14 13 -1 11 19 24 -1 24 19 18 -1 10 12 11 -1 11 12 19 -1 10 23 12 -1 12 23 17 -1 23 20 17 -1 17 20 13 -1 14 15 13 -1 13 15 16 -1 13 16 17 -1 17 16 5 -1 17 5 6 -1 6 18 17 -1 17 18 19 -1 17 19 12 -1 9 20 27 -1 27 20 21 -1 27 21 2 -1 20 23 21 -1 21 23 22 -1 22 23 25 -1 22 25 8 -1 10 11 23 -1 23 11 24 -1 23 24 25 -1 8 7 22 -1 2 26 27 -1 28 30 41 -1 41 30 42 -1 3 29 43 -1 43 29 33 -1 46 31 30 -1 30 31 42 -1 47 32 46 -1 46 32 31 -1 47 45 32 -1 32 45 35 -1 45 43 35 -1 35 43 33 -1 29 34 33 -1 33 34 40 -1 33 40 35 -1 35 40 37 -1 35 37 41 -1 41 37 36 -1 36 37 38 -1 34 39 40 -1 40 39 1 -1 41 42 35 -1 35 42 31 -1 35 31 32 -1 3 43 44 -1 44 43 0 -1 0 43 45 -1 0 45 4 -1 4 45 28 -1 28 45 30 -1 30 45 46 -1 46 45 47 -1 
            ]
          }
          physics Physics {
            density -1
            mass 5
            inertiaMatrix [
              2.000000e-01 3.000000e-01 4.000000e-01
              0.000000e+00 0.000000e+00 0.000000e+00
            ]
            centerOfMass 0 0 0
          }
        }
      }
      HingeJoint {
        jointParameters HingeJointParameters {
          axis 0.000000 1.000000 0.000000
          anchor -0.786500 -0.533400 0.203200
          dampingConstant 0.0
          staticFriction 0.0
        }
        device [
          RotationalMotor {
            name "base_to_wheel_back_left"
            maxVelocity 10.0
            maxTorque 1000.0
          }
          PositionSensor {
            name "base_to_wheel_back_left_sensor"
          }
        ]
        endPoint Solid {
          translation -0.786500 -0.533400 0.203200
          rotation 1.000000 0.000000 0.000000 0.000000
          children [
            Transform {
              translation -0.203200 0.000000 -0.203200
              rotation 0.000000 1.000000 0.000000 0.000000
              children [
                ForkliftRobot_wheel_0Mesh {
                }
              ]
            }
          ]
          name "wheel_back_left"
          boundingObject Transform {
            translation 0.000000 0.100000 0.000000
            rotation 1.000000 0.000000 -0.000000 3.141796
            children [
              Cylinder {
                radius 0.21
                height 0.2
              }
            ]
          }
          physics Physics {
            density -1
            mass 5
            inertiaMatrix [
              1.000000e-03 1.500000e-03 1.000000e-03
              0.000000e+00 0.000000e+00 0.000000e+00
            ]
            centerOfMass 0 0 0
          }
        }
      }
      HingeJoint {
        jointParameters HingeJointParameters {
          axis 0.000000 1.000000 0.000000
          anchor -0.750200 0.330200 0.203200
          dampingConstant 0.0
          staticFriction 0.0
        }
        device [
          RotationalMotor {
            name "base_to_wheel_back_right"
            maxVelocity 10.0
            maxTorque 1000.0
          }
          PositionSensor {
            name "base_to_wheel_back_right_sensor"
          }
        ]
        endPoint Solid {
          translation -0.750200 0.330200 0.203200
          rotation 1.000000 0.000000 0.000000 0.000000
          children [
            Transform {
              translation -0.203200 0.000000 -0.203200
              rotation 0.000000 1.000000 0.000000 0.000000
              children [
                ForkliftRobot_wheel_0Mesh {
                }
              ]
            }
          ]
          name "wheel_back_right"
          boundingObject Transform {
            translation 0.000000 0.100000 0.000000
            rotation 1.000000 0.000000 -0.000000 3.141796
            children [
              Cylinder {
                radius 0.21
                height 0.2
              }
            ]
          }
          physics Physics {
            density -1
            mass 5
            inertiaMatrix [
              1.000000e-03 1.500000e-03 1.000000e-03
              0.000000e+00 0.000000e+00 0.000000e+00
            ]
            centerOfMass 0 0 0
          }
        }
      }
      HingeJoint {
        jointParameters HingeJointParameters {
          axis 0.000000 1.000000 0.000000
          anchor 0.672200 0.330200 0.203200
          dampingConstant 0.0
          staticFriction 0.0
        }
        device [
          RotationalMotor {
            name "base_to_wheel_front_left"
            maxVelocity 10.0
            maxTorque 1000.0
          }
          PositionSensor {
            name "base_to_wheel_front_left_sensor"
          }
        ]
        endPoint Solid {
          translation 0.672200 0.330200 0.203200
          rotation 1.000000 0.000000 0.000000 0.000000
          children [
            Transform {
              translation -0.203200 0.000000 -0.203200
              rotation 0.000000 1.000000 0.000000 0.000000
              children [
                ForkliftRobot_wheel_0Mesh {
                }
              ]
            }
          ]
          name "wheel_front_left"
          boundingObject Transform {
            translation 0.000000 0.100000 0.000000
            rotation 1.000000 0.000000 -0.000000 3.141796
            children [
              Cylinder {
                radius 0.21
                height 0.2
              }
            ]
          }
          physics Physics {
            density -1
            mass 5
            inertiaMatrix [
              1.000000e-03 1.500000e-03 1.000000e-03
              0.000000e+00 0.000000e+00 0.000000e+00
            ]
            centerOfMass 0 0 0
          }
        }
      }
      HingeJoint {
        jointParameters HingeJointParameters {
          axis 0.000000 1.000000 0.000000
          anchor 0.672200 -0.533400 0.203200
          dampingConstant 0.0
          staticFriction 0.0
        }
        device [
          RotationalMotor {
            name "base_to_wheel_front_right"
            maxVelocity 10.0
            maxTorque 1000.0
          }
          PositionSensor {
            name "base_to_wheel_front_right_sensor"
          }
        ]
        endPoint Solid {
          translation 0.672200 -0.533400 0.203200
          rotation 1.000000 0.000000 0.000000 0.000000
          children [
            Transform {
              translation -0.203200 0.000000 -0.203200
              rotation 0.000000 1.000000 0.000000 0.000000
              children [
                ForkliftRobot_wheel_0Mesh {
                }
              ]
            }
          ]
          name "wheel_front_right"
          boundingObject Transform {
            translation 0.000000 0.100000 0.000000
            rotation 1.000000 0.000000 -0.000000 3.141796
            children [
              Cylinder {
                radius 0.21
                height 0.2
              }
            ]
          }
          physics Physics {
            density -1
            mass 5
            inertiaMatrix [
              1.000000e-03 1.500000e-03 1.000000e-03
              0.000000e+00 0.000000e+00 0.000000e+00
            ]
            centerOfMass 0 0 0
          }
        }
      }
    ]
    name IS name 
    boundingObject Transform {
      translation 0.000000 0.000000 1.371600
      rotation 0.000000 1.000000 0.000000 0.000000
      children [
        Box {
           size 2.159000 1.066800 2.743200
        }
      ]
    }
    physics Physics {
      density -1
      mass 500
      inertiaMatrix [
        2.060000e+02 3.890000e+02 3.160000e+02
        0.000000e+00 -2.300000e+01 0.000000e+00
      ]
      centerOfMass 0 0 0
    }
  }
}
