<?xml version="1.0"?>
<robot name="forklift_robot">
  <link name="base_link">
    <visual>
      <origin xyz="-1.0795 -0.5334 0" rpy="0 0 0" />
      <geometry>
        <mesh filename="package://forklift_robot_description/meshes/base_link.dae"/> 
      </geometry>
    </visual>
    <collision>
      <origin xyz="0 0 1.3716" rpy="0 0 0" />
      <geometry>
        <box size="2.159 1.0668 2.7432"/>
      </geometry>
    </collision>
    <inertial>
      <mass value="500"/>
      <inertia ixx="206" ixy="0" ixz="-23" iyy="389" iyz="0" izz="316"/>
    </inertial>
  </link>
  
  <link name="fork">
    <visual>
      <geometry>
        <mesh filename="package://forklift_robot_description/meshes/fork.dae"/> 
      </geometry>
    </visual>
    <collision>
      <geometry>
        <mesh filename="package://forklift_robot_description/meshes/fork.dae"/> 
      </geometry>
    </collision>
    <inertial>
      <mass value="100"/>
      <inertia ixx="0.2" ixy="0" ixz="0" iyy="0.3" iyz="0" izz="0.4"/>
    </inertial>
  </link>

  <link name="wheel_back_left">
    <visual>
      <origin xyz="-0.2032 0 -0.2032" rpy="0 0 0" />
      <geometry>
        <mesh filename="package://forklift_robot_description/meshes/wheel.dae"/> 
      </geometry>
    </visual>
    <collision>
      <origin xyz="0 0.1 0" rpy="1.571 0 0" />
      <geometry>
        <cylinder length="0.2" radius="0.21"/> 
      </geometry>
    </collision>
    <inertial>
      <mass value="5"/>
      <inertia ixx="0.001" ixy="0" ixz="0" iyy="0.0015" iyz="0" izz="0.001"/>
    </inertial>
  </link>
  
  <link name="wheel_back_right">
    <visual>
      <origin xyz="-0.2032 0 -0.2032" rpy="0 0 0" />
      <geometry>
        <mesh filename="package://forklift_robot_description/meshes/wheel.dae"/> 
      </geometry>
    </visual>
    <collision>
      <origin xyz="0 0.1 0" rpy="1.571 0 0" />
      <geometry>
        <cylinder length="0.2" radius="0.21"/> 
      </geometry>
    </collision>
    <inertial>
      <mass value="5"/>
      <inertia ixx="0.001" ixy="0" ixz="0" iyy="0.0015" iyz="0" izz="0.001"/>
    </inertial>
  </link>
  
  <link name="wheel_front_left">
    <visual>
      <origin xyz="-0.2032 0 -0.2032" rpy="0 0 0" />
      <geometry>
        <mesh filename="package://forklift_robot_description/meshes/wheel.dae"/> 
      </geometry>
    </visual>
    <collision>
      <origin xyz="0 0.1 0" rpy="1.571 0 0" />
      <geometry>
        <cylinder length="0.2" radius="0.21"/> 
      </geometry>
    </collision>
    <inertial>
      <mass value="5"/>
      <inertia ixx="0.001" ixy="0" ixz="0" iyy="0.0015" iyz="0" izz="0.001"/>
    </inertial>
  </link>
  
  <link name="wheel_front_right">
    <visual>
      <origin xyz="-0.2032 0 -0.2032" rpy="0 0 0" />
      <geometry>
        <mesh filename="package://forklift_robot_description/meshes/wheel.dae"/> 
      </geometry>
    </visual>
    <collision>
      <origin xyz="0 0.1 0" rpy="1.571 0 0" />
      <geometry>
        <cylinder length="0.2" radius="0.21"/> 
      </geometry>
    </collision>
    <inertial>
      <mass value="5"/>
      <inertia ixx="0.001" ixy="0" ixz="0" iyy="0.0015" iyz="0" izz="0.001"/>
    </inertial>
  </link>

  <joint name="base_to_fork" type="prismatic">
    <parent link="base_link"/>
    <child link="fork"/>
    <limit 
      lower="0" 
      upper="2" 
      velocity="0.1"
      effort="100"
    />
    <origin xyz="1.0795 -0.3686 0.0"/>
    <axis xyz="0 0 1"/>
  </joint>

  <joint name="base_to_wheel_back_left" type="continuous">
    <parent link="base_link"/>
    <child link="wheel_back_left"/>
    <limit 
      velocity="10"
      effort="1000"
    />
    <origin xyz="-0.7865 -0.5334 0.2032"/>
    <axis xyz="0 1 0"/>
  </joint>

  <joint name="base_to_wheel_back_right" type="continuous">
    <parent link="base_link"/>
    <child link="wheel_back_right"/>
    <limit 
      velocity="10"
      effort="1000"
    />
    <origin xyz="-0.7502 0.3302 0.2032"/>
    <axis xyz="0 1 0"/>
  </joint>

  <joint name="base_to_wheel_front_left" type="continuous">
    <parent link="base_link"/>
    <child link="wheel_front_left"/>
    <limit 
      velocity="10"
      effort="1000"
    />
    <origin xyz="0.6722 0.3302 0.2032"/>
    <axis xyz="0 1 0"/>
  </joint>

  <joint name="base_to_wheel_front_right" type="continuous">
    <parent link="base_link"/>
    <child link="wheel_front_right"/>
    <limit 
      velocity="10"
      effort="1000"
    />
    <origin xyz="0.6722 -0.5334 0.2032"/>
    <axis xyz="0 1 0"/>
  </joint>

  <sensor name="camera_sensor" update_rate="20">
    <parent link="base_link"/>
    <origin xyz="0 0 1.5" rpy="0 0 0" />
    <camera>
      <image width="640" height="480" hfov="1.5708" format="RGB8" near="0.01" far="50.0"/>
    </camera>
  </sensor>

  <sensor name="ray_sensor" update_rate="20">
   <parent link="basse_link"/>
   <origin xyz="0 0 1.5" rpy="0 0 0"/>
   <ray>
     <horizontal samples="100" resolution="1" min_angle="-1.5708" max_angle="1.5708"/>
     <vertical samples="1" resolution="1" min_angle="0" max_angle="0"/>
   </ray>
 </sensor>
</robot>